<?xml version="1.0" ?>
<!-- =================================================================================== -->
<!-- |    This document was autogenerated by xacro from sparke_description/src/urdf/sparke.xacro | -->
<!-- |    EDITING THIS FILE BY HAND IS NOT RECOMMENDED                                 | -->
<!-- =================================================================================== -->
<robot name="sparke">
  <material name="NinjaFlex_TPU">
    <color rgba="0.23529411764705882 0.23529411764705882 0.23529411764705882 1.0"/>
  </material>
  <material name="Generic">
    <color rgba="0.7490196078431373 0.7490196078431373 0.7490196078431373 1.0"/>
  </material>
  <material name="Sunlu_PETG">
    <color rgba="0.23529411764705882 0.23529411764705882 0.23529411764705882 1.0"/>
  </material>
  <material name="Prusament_PETG">
    <color rgba="0.054901960784313725 0.6470588235294118 0.7019607843137254 1.0"/>
  </material>
  <material name="Steel">
    <color rgba="1.0 1.0 1.0 1.0"/>
  </material>
  <material name="Cobalt_Chrome">
    <color rgba="1.0 1.0 1.0 1.0"/>
  </material>
  <material name="motor">
    <color rgba="0.7490196078431373 0.7490196078431373 0.7490196078431373 1.0"/>
  </material>
  <material name="Blue_Plastic">
    <color rgba="0.054901960784313725 0.6470588235294118 0.7019607843137254 1.0"/>
  </material>
  <gazebo>
    <plugin filename="ignition-gazebo-joint-state-publisher-system" name="ignition::gazebo::systems::JointStatePublisher"/>
  </gazebo>
  <link name="base_link">
    <inertial>
      <origin rpy="0.0 0.0 0.0" xyz="-2.6947797765e-03 -9.7783082216e-08 8.8991675475e-03"/>
      <mass value="5.8279616664e-02"/>
      <inertia ixx="9.6372603996e-05" ixy="-2.5829596652e-11" ixz="4.2310704061e-06" iyy="1.1254196713e-04" iyz="6.3753598513e-11" izz="1.9499602673e-04"/>
    </inertial>
    <visual>
      <origin rpy="0.0 0.0 0.0" xyz="0.0000000000e+00 0.0000000000e+00 0.0000000000e+00"/>
      <geometry>
        <mesh filename="file:///home/echo/workspaces/windows_scp/install/sparke_description/share/sparke_description/src/meshes/base.stl" scale="0.001 0.001 0.001"/>
      </geometry>
      <material name="Prusament_PETG"/>
    </visual>
    <collision>
      <origin rpy="0.0 0.0 0.0" xyz="0.0000000000e+00 0.0000000000e+00 0.0000000000e+00"/>
      <geometry>
        <mesh filename="file:///home/echo/workspaces/windows_scp/install/sparke_description/share/sparke_description/src/meshes/base.stl" scale="0.001 0.001 0.001"/>
      </geometry>
    </collision>
  </link>
  <link name="inner_front_shoulder_link">
    <inertial>
      <origin rpy="0.0 0.0 0.0" xyz="-7.5115476362e-03 -1.7083630825e-07 1.6382552785e-02"/>
      <mass value="6.8555867356e-02"/>
      <inertia ixx="5.7862869246e-05" ixy="4.3049829091e-10" ixz="6.1047073427e-06" iyy="6.0376210712e-05" iyz="1.8466002162e-10" izz="8.1626968761e-05"/>
    </inertial>
    <visual>
      <origin rpy="0.0 0.0 0.0" xyz="0.0 0.0 0.0"/>
      <geometry>
        <mesh filename="file:///home/echo/workspaces/windows_scp/install/sparke_description/share/sparke_description/src/meshes/inner_front_shoulder.stl" scale="0.001 0.001 0.001"/>
      </geometry>
      <material name="Sunlu_PETG"/>
    </visual>
    <collision>
      <origin rpy="0.0 0.0 0.0" xyz="0.0 0.0 0.0"/>
      <geometry>
        <mesh filename="file:///home/echo/workspaces/windows_scp/install/sparke_description/share/sparke_description/src/meshes/inner_front_shoulder.stl" scale="0.001 0.001 0.001"/>
      </geometry>
      <contact_coefficients kd="200" kp="50000" mu="0.35"/>
    </collision>
  </link>
  <joint name="Rigid 1_joint" type="fixed">
    <origin rpy="-0.0 1.570796 0.0" xyz="6.5000009537e-02 9.5345922091e-09 3.7000002861e-02"/>
    <parent link="base_link"/>
    <child link="inner_front_shoulder_link"/>
  </joint>
  <link name="front_outer_shoulder_link">
    <inertial>
      <origin rpy="0.0 0.0 0.0" xyz="6.7549462183e-04 7.6825917006e-10 2.3644006725e-03"/>
      <mass value="2.6957423176e-02"/>
      <inertia ixx="3.1060161566e-05" ixy="2.6585036690e-13" ixz="-3.2680288790e-08" iyy="1.1480283704e-05" iyz="-5.2712213033e-14" izz="4.2428019792e-05"/>
    </inertial>
    <visual>
      <origin rpy="0.0 0.0 0.0" xyz="0.0 0.0 0.0"/>
      <geometry>
        <mesh filename="file:///home/echo/workspaces/windows_scp/install/sparke_description/share/sparke_description/src/meshes/front_outer_shoulder.stl" scale="0.001 0.001 0.001"/>
      </geometry>
      <material name="Sunlu_PETG"/>
    </visual>
    <collision>
      <origin rpy="0.0 0.0 0.0" xyz="0.0 0.0 0.0"/>
      <geometry>
        <mesh filename="file:///home/echo/workspaces/windows_scp/install/sparke_description/share/sparke_description/src/meshes/front_outer_shoulder.stl" scale="0.001 0.001 0.001"/>
      </geometry>
      <contact_coefficients kd="200" kp="50000" mu="0.35"/>
    </collision>
  </link>
  <joint name="Rigid 45_joint" type="fixed">
    <origin rpy="0.0 0.0 0.0" xyz="-2.4366991980e-09 -2.8421709430e-16 5.2500000000e-02"/>
    <parent link="inner_front_shoulder_link"/>
    <child link="front_outer_shoulder_link"/>
  </joint>
  <link name="front_left_shoulder_motor_link">
    <inertial>
      <origin rpy="0.0 0.0 0.0" xyz="2.4770417463e-02 -6.4651608023e-18 9.9190738732e-03"/>
      <mass value="6.5151227692e-02"/>
      <inertia ixx="1.1288651801e-05" ixy="-1.1134501294e-20" ixz="-1.1184552052e-07" iyy="1.7807951326e-05" iyz="-1.6567946312e-11" izz="1.0838593450e-05"/>
    </inertial>
    <visual>
      <origin rpy="0.0 0.0 0.0" xyz="2.5100000000e-02 4.4408920985e-18 1.0000000000e-02"/>
      <geometry>
        <mesh filename="file:///home/echo/workspaces/windows_scp/install/sparke_description/share/sparke_description/src/meshes/front_left_shoulder_motor.stl" scale="0.001 0.001 0.001"/>
      </geometry>
      <material name="motor"/>
    </visual>
    <collision>
      <origin rpy="0.0 0.0 0.0" xyz="2.5100000000e-02 4.4408920985e-18 1.0000000000e-02"/>
      <geometry>
        <mesh filename="file:///home/echo/workspaces/windows_scp/install/sparke_description/share/sparke_description/src/meshes/front_left_shoulder_motor.stl" scale="0.001 0.001 0.001"/>
      </geometry>
    </collision>
  </link>
  <joint name="front_left_shoulder_motor_joint" type="revolute">
    <origin rpy="-1.068103 1.570774 -1.068103" xyz="-9.0004342461e-03 3.9000992478e-02 1.4476511425e-03"/>
    <parent link="front_outer_shoulder_link"/>
    <child link="front_left_shoulder_motor_link"/>
    <axis xyz="1.0 -0.0 0.0"/>
    <limit effort="1000.0" lower="-0.785398" upper="0.785398" velocity="100.0"/>
  </joint>
  <link name="front_left_shoulder_link">
    <inertial>
      <origin rpy="0.0 0.0 0.0" xyz="-8.9077955019e-06 -1.5208944042e-03 1.4685782418e-02"/>
      <mass value="2.9364453561e-02"/>
      <inertia ixx="6.4062059945e-06" ixy="-1.2379545470e-08" ixz="5.6097747280e-09" iyy="1.0209186052e-05" iyz="4.1877426524e-07" izz="1.1725885400e-05"/>
    </inertial>
    <visual>
      <origin rpy="0.0 0.0 0.0" xyz="0.0 0.0 0.0"/>
      <geometry>
        <mesh filename="file:///home/echo/workspaces/windows_scp/install/sparke_description/share/sparke_description/src/meshes/front_left_shoulder.stl" scale="0.001 0.001 0.001"/>
      </geometry>
      <material name="Sunlu_PETG"/>
    </visual>
    <collision>
      <origin rpy="0.0 0.0 0.0" xyz="0.0 0.0 0.0"/>
      <geometry>
        <mesh filename="file:///home/echo/workspaces/windows_scp/install/sparke_description/share/sparke_description/src/meshes/front_left_shoulder.stl" scale="0.001 0.001 0.001"/>
      </geometry>
      <contact_coefficients kd="200" kp="50000" mu="0.35"/>
    </collision>
  </link>
  <joint name="Rigid 5_joint" type="fixed">
    <origin rpy="-1.570805 -1.570763 3.141593" xyz="2.7199350095e-02 2.7500186774e-02 1.0749048248e-02"/>
    <parent link="front_left_shoulder_motor_link"/>
    <child link="front_left_shoulder_link"/>
  </joint>
  <link name="front_left_shoulder_bearing_link">
    <inertial>
      <origin rpy="0.0 0.0 0.0" xyz="3.0148293091e-16 5.6032859591e-11 2.3512298002e-03"/>
      <mass value="5.6361450987e-03"/>
      <inertia ixx="1.2650699176e-07" ixy="-2.6932166482e-21" ixz="2.0950551704e-20" iyy="1.2650699201e-07" iyz="2.3906884669e-15" izz="2.2677705019e-07"/>
    </inertial>
    <visual>
      <origin rpy="0.0 0.0 0.0" xyz="0.0 0.0 0.0"/>
      <geometry>
        <mesh filename="file:///home/echo/workspaces/windows_scp/install/sparke_description/share/sparke_description/src/meshes/front_left_shoulder_bearing.stl" scale="0.001 0.001 0.001"/>
      </geometry>
      <material name="Steel"/>
    </visual>
    <collision>
      <origin rpy="0.0 0.0 0.0" xyz="0.0 0.0 0.0"/>
      <geometry>
        <mesh filename="file:///home/echo/workspaces/windows_scp/install/sparke_description/share/sparke_description/src/meshes/front_left_shoulder_bearing.stl" scale="0.001 0.001 0.001"/>
      </geometry>
    </collision>
  </link>
  <joint name="Rigid 6_joint" type="fixed">
    <origin rpy="-1.570824 -0.0 3.141548" xyz="-1.0749865922e-02 -2.1748169408e-02 2.7500033921e-02"/>
    <parent link="front_left_shoulder_link"/>
    <child link="front_left_shoulder_bearing_link"/>
  </joint>
  <link name="front_left_shoulder_reinforcement_link">
    <inertial>
      <origin rpy="0.0 0.0 0.0" xyz="-4.6572479340e-03 9.5331124904e-03 8.4629007410e-03"/>
      <mass value="2.2660325718e-02"/>
      <inertia ixx="1.5432003406e-05" ixy="-4.1387965314e-07" ixz="-3.0777192107e-07" iyy="4.5422124673e-06" iyz="-2.9735718887e-06" izz="1.5123547672e-05"/>
    </inertial>
    <visual>
      <origin rpy="0.0 0.0 0.0" xyz="0.0 0.0 0.0"/>
      <geometry>
        <mesh filename="file:///home/echo/workspaces/windows_scp/install/sparke_description/share/sparke_description/src/meshes/front_left_shoulder_reinforcement.stl" scale="0.001 0.001 0.001"/>
      </geometry>
      <material name="Prusament_PETG"/>
    </visual>
    <collision>
      <origin rpy="0.0 0.0 0.0" xyz="0.0 0.0 0.0"/>
      <geometry>
        <mesh filename="file:///home/echo/workspaces/windows_scp/install/sparke_description/share/sparke_description/src/meshes/front_left_shoulder_reinforcement.stl" scale="0.001 0.001 0.001"/>
      </geometry>
      <contact_coefficients kd="200" kp="50000" mu="0.35"/>
    </collision>
  </link>
  <joint name="Rigid 13_joint" type="fixed">
    <origin rpy="-1.570796 0.0 -1.570796" xyz="-3.3371861108e-02 2.5071821888e-03 -1.3628472706e-02"/>
    <parent link="front_left_shoulder_link"/>
    <child link="front_left_shoulder_reinforcement_link"/>
  </joint>
  <link name="front_left_reinforcement_bearing_link">
    <inertial>
      <origin rpy="0.0 0.0 0.0" xyz="3.0148293091e-16 5.6032859591e-11 2.3512298002e-03"/>
      <mass value="5.6361450987e-03"/>
      <inertia ixx="1.2650699176e-07" ixy="-2.6932166482e-21" ixz="2.0950551704e-20" iyy="1.2650699201e-07" iyz="2.3906884669e-15" izz="2.2677705019e-07"/>
    </inertial>
    <visual>
      <origin rpy="0.0 0.0 0.0" xyz="0.0 0.0 0.0"/>
      <geometry>
        <mesh filename="file:///home/echo/workspaces/windows_scp/install/sparke_description/share/sparke_description/src/meshes/front_left_reinforcement_bearing.stl" scale="0.001 0.001 0.001"/>
      </geometry>
      <material name="Steel"/>
    </visual>
    <collision>
      <origin rpy="0.0 0.0 0.0" xyz="0.0 0.0 0.0"/>
      <geometry>
        <mesh filename="file:///home/echo/workspaces/windows_scp/install/sparke_description/share/sparke_description/src/meshes/front_left_reinforcement_bearing.stl" scale="0.001 0.001 0.001"/>
      </geometry>
    </collision>
  </link>
  <joint name="Rigid 17_joint" type="fixed">
    <origin rpy="-1.570796 0.0 0.0" xyz="2.5071670580e-03 3.5246565463e-02 3.3371712009e-02"/>
    <parent link="front_left_shoulder_reinforcement_link"/>
    <child link="front_left_reinforcement_bearing_link"/>
  </joint>
  <link name="front_left_leg_motor_link">
    <inertial>
      <origin rpy="0.0 0.0 0.0" xyz="2.4770417463e-02 -6.4651608023e-18 9.9190738732e-03"/>
      <mass value="6.5151227692e-02"/>
      <inertia ixx="1.1288651801e-05" ixy="-1.1134501294e-20" ixz="-1.1184552052e-07" iyy="1.7807951326e-05" iyz="-1.6567946312e-11" izz="1.0838593450e-05"/>
    </inertial>
    <visual>
      <origin rpy="0.0 0.0 0.0" xyz="2.5100000000e-02 4.4408920985e-18 1.0000000000e-02"/>
      <geometry>
        <mesh filename="file:///home/echo/workspaces/windows_scp/install/sparke_description/share/sparke_description/src/meshes/front_left_leg_motor.stl" scale="0.001 0.001 0.001"/>
      </geometry>
      <material name="motor"/>
    </visual>
    <collision>
      <origin rpy="0.0 0.0 0.0" xyz="2.5100000000e-02 4.4408920985e-18 1.0000000000e-02"/>
      <geometry>
        <mesh filename="file:///home/echo/workspaces/windows_scp/install/sparke_description/share/sparke_description/src/meshes/front_left_leg_motor.stl" scale="0.001 0.001 0.001"/>
      </geometry>
    </collision>
  </link>
  <joint name="front_left_leg_motor_joint" type="revolute">
    <origin rpy="-0.743689 1.570795 -1.616354" xyz="1.6788098166e-07 7.4256393923e-09 2.7999343907e-03"/>
    <parent link="front_left_shoulder_link"/>
    <child link="front_left_leg_motor_link"/>
    <axis xyz="1.0 0.0 0.0"/>
    <limit effort="1000.0" lower="-2.181662" upper="1.832596" velocity="100.0"/>
  </joint>
  <link name="front_left_leg_link">
    <inertial>
      <origin rpy="0.0 0.0 0.0" xyz="-5.4606100052e-02 2.3375508028e-02 -1.0302815208e-02"/>
      <mass value="6.6454472204e-02"/>
      <inertia ixx="1.0985672324e-05" ixy="6.1986854700e-06" ixz="2.7421282493e-06" iyy="6.1094164263e-05" iyz="1.4589221151e-07" izz="6.3552877469e-05"/>
    </inertial>
    <visual>
      <origin rpy="0.0 0.0 0.0" xyz="0.0 0.0 0.0"/>
      <geometry>
        <mesh filename="file:///home/echo/workspaces/windows_scp/install/sparke_description/share/sparke_description/src/meshes/front_left_leg.stl" scale="0.001 0.001 0.001"/>
      </geometry>
      <material name="Sunlu_PETG"/>
    </visual>
    <collision>
      <origin rpy="0.0 0.0 0.0" xyz="0.0 0.0 0.0"/>
      <geometry>
        <mesh filename="file:///home/echo/workspaces/windows_scp/install/sparke_description/share/sparke_description/src/meshes/front_left_leg.stl" scale="0.001 0.001 0.001"/>
      </geometry>
      <contact_coefficients kd="200" kp="50000" mu="0.35"/>
    </collision>
  </link>
  <joint name="Rigid 22_joint" type="fixed">
    <origin rpy="-1.570796 -1.570796 0.0" xyz="4.9499961853e-03 1.3819298880e-02 1.0742515781e-01"/>
    <parent link="front_left_leg_motor_link"/>
    <child link="front_left_leg_link"/>
  </joint>
  <link name="front_left_wrist_motor_link">
    <inertial>
      <origin rpy="0.0 0.0 0.0" xyz="2.4770417463e-02 -1.0906052901e-17 9.9190738732e-03"/>
      <mass value="6.5151227692e-02"/>
      <inertia ixx="1.1288651801e-05" ixy="-1.1134501294e-20" ixz="-1.1184552052e-07" iyy="1.7807951326e-05" iyz="-1.6567946312e-11" izz="1.0838593450e-05"/>
    </inertial>
    <visual>
      <origin rpy="0.0 0.0 0.0" xyz="2.5100000000e-02 0.0000000000e+00 1.0000000000e-02"/>
      <geometry>
        <mesh filename="file:///home/echo/workspaces/windows_scp/install/sparke_description/share/sparke_description/src/meshes/front_left_wrist_motor.stl" scale="0.001 0.001 0.001"/>
      </geometry>
      <material name="motor"/>
    </visual>
    <collision>
      <origin rpy="0.0 0.0 0.0" xyz="2.5100000000e-02 0.0000000000e+00 1.0000000000e-02"/>
      <geometry>
        <mesh filename="file:///home/echo/workspaces/windows_scp/install/sparke_description/share/sparke_description/src/meshes/front_left_wrist_motor.stl" scale="0.001 0.001 0.001"/>
      </geometry>
    </collision>
  </link>
  <joint name="front_left_wrist_motor_joint" type="revolute">
    <origin rpy="-0.052359 -2e-06 1.570846" xyz="2.3096291962e-06 1.6529780064e-03 2.5792573342e-07"/>
    <parent link="front_left_leg_link"/>
    <child link="front_left_wrist_motor_link"/>
    <axis xyz="1.0 0.0 0.0"/>
    <limit effort="1000.0" lower="-2.530727" upper="0.872665" velocity="100.0"/>
  </joint>
  <link name="front_left_wrist_link">
    <inertial>
      <origin rpy="0.0 0.0 0.0" xyz="4.9747178430e-02 4.7847093617e-03 1.3421230556e-02"/>
      <mass value="3.4551036819e-02"/>
      <inertia ixx="5.2044527700e-06" ixy="3.5730960450e-06" ixz="-4.9756329095e-06" iyy="8.1559081128e-05" iyz="4.1340818971e-07" izz="8.1109521282e-05"/>
    </inertial>
    <visual>
      <origin rpy="0.0 0.0 0.0" xyz="0.0 0.0 0.0"/>
      <geometry>
        <mesh filename="file:///home/echo/workspaces/windows_scp/install/sparke_description/share/sparke_description/src/meshes/front_left_wrist.stl" scale="0.001 0.001 0.001"/>
      </geometry>
      <material name="Sunlu_PETG"/>
    </visual>
    <collision>
      <origin rpy="0.0 0.0 0.0" xyz="0.0 0.0 0.0"/>
      <geometry>
        <mesh filename="file:///home/echo/workspaces/windows_scp/install/sparke_description/share/sparke_description/src/meshes/front_left_wrist.stl" scale="0.001 0.001 0.001"/>
      </geometry>
      <contact_coefficients kd="200" kp="50000" mu="0.35"/>
    </collision>
  </link>
  <joint name="Rigid 21_joint" type="fixed">
    <origin rpy="-1.570796 -1.570796 0.0" xyz="2.3706227782e-02 -1.4999999384e-02 3.2615342478e-03"/>
    <parent link="front_left_wrist_motor_link"/>
    <child link="front_left_wrist_link"/>
  </joint>
  <link name="front_left_foot_link">
    <contact>
      <stiffness value="10000"/>
      <damping value="10"/>
      <lateral_friction value="1"/>
    </contact>
    <inertial>
      <origin rpy="0.0 0.0 0.0" xyz="-6.2511651463e-07 1.4767339683e-08 -2.9531449039e-04"/>
      <mass value="4.0610139569e-03"/>
      <inertia ixx="2.1736705869e-07" ixy="3.2711759586e-12" ixz="3.0436497378e-12" iyy="6.5294667216e-07" iyz="-5.8438631289e-13" izz="6.4784298190e-07"/>
    </inertial>
    <visual>
      <origin rpy="0.0 0.0 0.0" xyz="0.0 0.0 0.0"/>
      <geometry>
        <mesh filename="file:///home/echo/workspaces/windows_scp/install/sparke_description/share/sparke_description/src/meshes/front_left_foot.stl" scale="0.001 0.001 0.001"/>
      </geometry>
      <material name="NinjaFlex_TPU"/>
    </visual>
    <collision>
      <origin rpy="0.0 0.0 0.0" xyz="0.0 0.0 0.0"/>
      <geometry>
        <mesh filename="file:///home/echo/workspaces/windows_scp/install/sparke_description/share/sparke_description/src/meshes/front_left_foot.stl" scale="0.001 0.001 0.001"/>
      </geometry>
      <contact_coefficients kd="100" kp="10000" mu="0.8"/>
    </collision>
  </link>
  <joint name="Rigid 51_joint" type="fixed">
    <origin rpy="-0.0 -1.221725 0.0" xyz="1.2235978642e-01 2.2436615026e-03 1.1681321796e-02"/>
    <parent link="front_left_wrist_link"/>
    <child link="front_left_foot_link"/>
  </joint>
  <link name="front_left_leg_cover_link">
    <inertial>
      <origin rpy="0.0 0.0 0.0" xyz="-6.3642567032e-02 -1.6626829366e-02 -1.0807825161e-02"/>
      <mass value="3.2616672507e-02"/>
      <inertia ixx="6.5685289932e-06" ixy="-7.1216478366e-06" ixz="2.6597436857e-06" iyy="6.1594213073e-05" iyz="-7.6240704761e-07" izz="6.3063527195e-05"/>
    </inertial>
    <visual>
      <origin rpy="0.0 0.0 0.0" xyz="0.0 0.0 0.0"/>
      <geometry>
        <mesh filename="file:///home/echo/workspaces/windows_scp/install/sparke_description/share/sparke_description/src/meshes/front_left_leg_cover.stl" scale="0.001 0.001 0.001"/>
      </geometry>
      <material name="Blue_Plastic"/>
    </visual>
    <collision>
      <origin rpy="0.0 0.0 0.0" xyz="0.0 0.0 0.0"/>
      <geometry>
        <mesh filename="file:///home/echo/workspaces/windows_scp/install/sparke_description/share/sparke_description/src/meshes/front_left_leg_cover.stl" scale="0.001 0.001 0.001"/>
      </geometry>
      <contact_coefficients kd="200" kp="50000" mu="0.35"/>
    </collision>
  </link>
  <joint name="Rigid 57_joint" type="fixed">
    <origin rpy="2e-06 -0.052359 5.1e-05" xyz="2.2890273899e-09 5.6001248125e-02 -9.3081263586e-10"/>
    <parent link="front_left_leg_link"/>
    <child link="front_left_leg_cover_link"/>
  </joint>
  <link name="front_left_leg_bearing_link">
    <inertial>
      <origin rpy="0.0 0.0 0.0" xyz="3.0148293091e-16 5.6032859591e-11 2.3512298002e-03"/>
      <mass value="5.6361450987e-03"/>
      <inertia ixx="1.2650699176e-07" ixy="-2.6932166482e-21" ixz="2.0950551704e-20" iyy="1.2650699201e-07" iyz="2.3906884669e-15" izz="2.2677705019e-07"/>
    </inertial>
    <visual>
      <origin rpy="0.0 0.0 0.0" xyz="0.0 0.0 0.0"/>
      <geometry>
        <mesh filename="file:///home/echo/workspaces/windows_scp/install/sparke_description/share/sparke_description/src/meshes/front_left_leg_bearing.stl" scale="0.001 0.001 0.001"/>
      </geometry>
      <material name="Steel"/>
    </visual>
    <collision>
      <origin rpy="0.0 0.0 0.0" xyz="0.0 0.0 0.0"/>
      <geometry>
        <mesh filename="file:///home/echo/workspaces/windows_scp/install/sparke_description/share/sparke_description/src/meshes/front_left_leg_bearing.stl" scale="0.001 0.001 0.001"/>
      </geometry>
    </collision>
  </link>
  <joint name="Rigid 61_joint" type="fixed">
    <origin rpy="1.570796 -0.0 3.141592" xyz="-3.9964286455e-07 -4.9999552941e-03 4.0907933911e-07"/>
    <parent link="front_left_leg_cover_link"/>
    <child link="front_left_leg_bearing_link"/>
  </joint>
  <link name="front_right_shoulder_motor_link">
    <inertial>
      <origin rpy="0.0 0.0 0.0" xyz="2.4770417463e-02 -2.0242687038e-18 -9.9190738732e-03"/>
      <mass value="6.5151227692e-02"/>
      <inertia ixx="1.1288651801e-05" ixy="-1.1134501294e-20" ixz="1.1184552052e-07" iyy="1.7807951326e-05" iyz="1.6567946287e-11" izz="1.0838593450e-05"/>
    </inertial>
    <visual>
      <origin rpy="0.0 0.0 0.0" xyz="2.5100000000e-02 8.8817841970e-18 -1.0000000000e-02"/>
      <geometry>
        <mesh filename="file:///home/echo/workspaces/windows_scp/install/sparke_description/share/sparke_description/src/meshes/front_right_shoulder_motor.stl" scale="0.001 0.001 0.001"/>
      </geometry>
      <material name="motor"/>
    </visual>
    <collision>
      <origin rpy="0.0 0.0 0.0" xyz="2.5100000000e-02 8.8817841970e-18 -1.0000000000e-02"/>
      <geometry>
        <mesh filename="file:///home/echo/workspaces/windows_scp/install/sparke_description/share/sparke_description/src/meshes/front_right_shoulder_motor.stl" scale="0.001 0.001 0.001"/>
      </geometry>
    </collision>
  </link>
  <joint name="front_right_shoulder_motor_joint" type="revolute">
    <origin rpy="-2.07349 1.570774 1.068103" xyz="-9.0004342461e-03 -3.9000975487e-02 1.4476511425e-03"/>
    <parent link="front_outer_shoulder_link"/>
    <child link="front_right_shoulder_motor_link"/>
    <axis xyz="-1.0 -0.0 0.0"/>
    <limit effort="1000.0" lower="-0.785398" upper="0.785398" velocity="100.0"/>
  </joint>
  <link name="front_right_shoulder_link">
    <inertial>
      <origin rpy="0.0 0.0 0.0" xyz="-8.9121600367e-06 -1.5211509529e-03 -1.4685633137e-02"/>
      <mass value="2.9364763609e-02"/>
      <inertia ixx="6.4063207202e-06" ixy="-1.2324133327e-08" ixz="-5.5676552781e-09" iyy="1.0209381952e-05" iyz="-4.1881957681e-07" izz="1.1726316518e-05"/>
    </inertial>
    <visual>
      <origin rpy="0.0 0.0 0.0" xyz="0.0 0.0 0.0"/>
      <geometry>
        <mesh filename="file:///home/echo/workspaces/windows_scp/install/sparke_description/share/sparke_description/src/meshes/front_right_shoulder.stl" scale="0.001 0.001 0.001"/>
      </geometry>
      <material name="Sunlu_PETG"/>
    </visual>
    <collision>
      <origin rpy="0.0 0.0 0.0" xyz="0.0 0.0 0.0"/>
      <geometry>
        <mesh filename="file:///home/echo/workspaces/windows_scp/install/sparke_description/share/sparke_description/src/meshes/front_right_shoulder.stl" scale="0.001 0.001 0.001"/>
      </geometry>
      <contact_coefficients kd="200" kp="50000" mu="0.35"/>
    </collision>
  </link>
  <joint name="Rigid 7_joint" type="fixed">
    <origin rpy="1.570805 1.570763 3.141593" xyz="2.7199350095e-02 2.7500186774e-02 -1.0749048248e-02"/>
    <parent link="front_right_shoulder_motor_link"/>
    <child link="front_right_shoulder_link"/>
  </joint>
  <link name="front_right_shoulder_bearing_link">
    <inertial>
      <origin rpy="0.0 0.0 0.0" xyz="-8.6685400989e-16 5.6030562235e-11 -2.3512297438e-03"/>
      <mass value="5.9520565592e-03"/>
      <inertia ixx="1.3359783030e-07" ixy="-2.2927042065e-20" ixz="-1.3678465234e-20" iyy="1.3359783057e-07" iyz="-2.5246651363e-15" izz="2.3948812052e-07"/>
    </inertial>
    <visual>
      <origin rpy="0.0 0.0 0.0" xyz="0.0 0.0 0.0"/>
      <geometry>
        <mesh filename="file:///home/echo/workspaces/windows_scp/install/sparke_description/share/sparke_description/src/meshes/front_right_shoulder_bearing.stl" scale="0.001 0.001 0.001"/>
      </geometry>
      <material name="Cobalt_Chrome"/>
    </visual>
    <collision>
      <origin rpy="0.0 0.0 0.0" xyz="0.0 0.0 0.0"/>
      <geometry>
        <mesh filename="file:///home/echo/workspaces/windows_scp/install/sparke_description/share/sparke_description/src/meshes/front_right_shoulder_bearing.stl" scale="0.001 0.001 0.001"/>
      </geometry>
    </collision>
  </link>
  <joint name="Rigid 8_joint" type="fixed">
    <origin rpy="1.570824 0.0 3.141548" xyz="-1.0749865922e-02 -2.1748169408e-02 -2.7500033921e-02"/>
    <parent link="front_right_shoulder_link"/>
    <child link="front_right_shoulder_bearing_link"/>
  </joint>
  <link name="front_right_shoulder_reinforcement_link">
    <inertial>
      <origin rpy="0.0 0.0 0.0" xyz="-4.6571345170e-03 9.5334507238e-03 -8.4629481940e-03"/>
      <mass value="2.2660594722e-02"/>
      <inertia ixx="1.5432217957e-05" ixy="-4.1394328355e-07" ixz="3.0777468508e-07" iyy="4.5423320189e-06" iyz="2.9736040956e-06" izz="1.5123941735e-05"/>
    </inertial>
    <visual>
      <origin rpy="0.0 0.0 0.0" xyz="0.0 0.0 0.0"/>
      <geometry>
        <mesh filename="file:///home/echo/workspaces/windows_scp/install/sparke_description/share/sparke_description/src/meshes/front_right_shoulder_reinforcement.stl" scale="0.001 0.001 0.001"/>
      </geometry>
      <material name="Prusament_PETG"/>
    </visual>
    <collision>
      <origin rpy="0.0 0.0 0.0" xyz="0.0 0.0 0.0"/>
      <geometry>
        <mesh filename="file:///home/echo/workspaces/windows_scp/install/sparke_description/share/sparke_description/src/meshes/front_right_shoulder_reinforcement.stl" scale="0.001 0.001 0.001"/>
      </geometry>
      <contact_coefficients kd="200" kp="50000" mu="0.35"/>
    </collision>
  </link>
  <joint name="Rigid 14_joint" type="fixed">
    <origin rpy="1.570796 0.0 -1.570796" xyz="-3.3371861108e-02 2.5071821888e-03 1.3628472706e-02"/>
    <parent link="front_right_shoulder_link"/>
    <child link="front_right_shoulder_reinforcement_link"/>
  </joint>
  <link name="front_right_reinforcement_bearing_link">
    <inertial>
      <origin rpy="0.0 0.0 0.0" xyz="-8.6685400989e-16 5.6030562235e-11 -2.3512297438e-03"/>
      <mass value="5.9520565592e-03"/>
      <inertia ixx="1.3359783030e-07" ixy="-2.2927042065e-20" ixz="-1.3678465234e-20" iyy="1.3359783057e-07" iyz="-2.5246651363e-15" izz="2.3948812052e-07"/>
    </inertial>
    <visual>
      <origin rpy="0.0 0.0 0.0" xyz="0.0 0.0 0.0"/>
      <geometry>
        <mesh filename="file:///home/echo/workspaces/windows_scp/install/sparke_description/share/sparke_description/src/meshes/front_right_reinforcement_bearing.stl" scale="0.001 0.001 0.001"/>
      </geometry>
      <material name="Cobalt_Chrome"/>
    </visual>
    <collision>
      <origin rpy="0.0 0.0 0.0" xyz="0.0 0.0 0.0"/>
      <geometry>
        <mesh filename="file:///home/echo/workspaces/windows_scp/install/sparke_description/share/sparke_description/src/meshes/front_right_reinforcement_bearing.stl" scale="0.001 0.001 0.001"/>
      </geometry>
    </collision>
  </link>
  <joint name="Rigid 18_joint" type="fixed">
    <origin rpy="1.570796 0.0 0.0" xyz="2.5071670580e-03 3.5246565463e-02 -3.3371712009e-02"/>
    <parent link="front_right_shoulder_reinforcement_link"/>
    <child link="front_right_reinforcement_bearing_link"/>
  </joint>
  <link name="front_right_leg_motor_link">
    <inertial>
      <origin rpy="0.0 0.0 0.0" xyz="2.4770417463e-02 -2.4228729197e-17 -9.9190738732e-03"/>
      <mass value="6.5151227692e-02"/>
      <inertia ixx="1.1288651801e-05" ixy="-1.1134501294e-20" ixz="1.1184552052e-07" iyy="1.7807951326e-05" iyz="1.6567946287e-11" izz="1.0838593450e-05"/>
    </inertial>
    <visual>
      <origin rpy="0.0 0.0 0.0" xyz="2.5100000000e-02 -1.3322676296e-17 -1.0000000000e-02"/>
      <geometry>
        <mesh filename="file:///home/echo/workspaces/windows_scp/install/sparke_description/share/sparke_description/src/meshes/front_right_leg_motor.stl" scale="0.001 0.001 0.001"/>
      </geometry>
      <material name="motor"/>
    </visual>
    <collision>
      <origin rpy="0.0 0.0 0.0" xyz="2.5100000000e-02 -1.3322676296e-17 -1.0000000000e-02"/>
      <geometry>
        <mesh filename="file:///home/echo/workspaces/windows_scp/install/sparke_description/share/sparke_description/src/meshes/front_right_leg_motor.stl" scale="0.001 0.001 0.001"/>
      </geometry>
    </collision>
  </link>
  <joint name="front_right_leg_motor_joint" type="revolute">
    <origin rpy="0.743689 -1.570795 -1.616354" xyz="1.6788098173e-07 7.4256394278e-09 -2.7999343907e-03"/>
    <parent link="front_right_shoulder_link"/>
    <child link="front_right_leg_motor_link"/>
    <axis xyz="-1.0 0.0 0.0"/>
    <limit effort="1000.0" lower="-2.181662" upper="1.832596" velocity="100.0"/>
  </joint>
  <link name="front_right_leg_link">
    <inertial>
      <origin rpy="0.0 0.0 0.0" xyz="-5.4606863575e-02 2.3375791873e-02 1.0302959638e-02"/>
      <mass value="6.6453546159e-02"/>
      <inertia ixx="1.0985156700e-05" ixy="6.1976523397e-06" ixz="-2.7426543313e-06" iyy="6.1091216708e-05" iyz="-1.4569549428e-07" izz="6.3549678677e-05"/>
    </inertial>
    <visual>
      <origin rpy="0.0 0.0 0.0" xyz="0.0 0.0 0.0"/>
      <geometry>
        <mesh filename="file:///home/echo/workspaces/windows_scp/install/sparke_description/share/sparke_description/src/meshes/front_right_leg.stl" scale="0.001 0.001 0.001"/>
      </geometry>
      <material name="Sunlu_PETG"/>
    </visual>
    <collision>
      <origin rpy="0.0 0.0 0.0" xyz="0.0 0.0 0.0"/>
      <geometry>
        <mesh filename="file:///home/echo/workspaces/windows_scp/install/sparke_description/share/sparke_description/src/meshes/front_right_leg.stl" scale="0.001 0.001 0.001"/>
      </geometry>
      <contact_coefficients kd="200" kp="50000" mu="0.35"/>
    </collision>
  </link>
  <joint name="Rigid 26_joint" type="fixed">
    <origin rpy="1.570796 1.570796 0.0" xyz="4.9499961853e-03 1.3819298880e-02 -1.0742515781e-01"/>
    <parent link="front_right_leg_motor_link"/>
    <child link="front_right_leg_link"/>
  </joint>
  <link name="front_right_wrist_motor_link">
    <inertial>
      <origin rpy="0.0 0.0 0.0" xyz="2.4770417463e-02 -1.5346944999e-17 -9.9190738732e-03"/>
      <mass value="6.5151227692e-02"/>
      <inertia ixx="1.1288651801e-05" ixy="-1.1134501294e-20" ixz="1.1184552052e-07" iyy="1.7807951326e-05" iyz="1.6567946287e-11" izz="1.0838593450e-05"/>
    </inertial>
    <visual>
      <origin rpy="0.0 0.0 0.0" xyz="2.5100000000e-02 -4.4408920985e-18 -1.0000000000e-02"/>
      <geometry>
        <mesh filename="file:///home/echo/workspaces/windows_scp/install/sparke_description/share/sparke_description/src/meshes/front_right_wrist_motor.stl" scale="0.001 0.001 0.001"/>
      </geometry>
      <material name="motor"/>
    </visual>
    <collision>
      <origin rpy="0.0 0.0 0.0" xyz="2.5100000000e-02 -4.4408920985e-18 -1.0000000000e-02"/>
      <geometry>
        <mesh filename="file:///home/echo/workspaces/windows_scp/install/sparke_description/share/sparke_description/src/meshes/front_right_wrist_motor.stl" scale="0.001 0.001 0.001"/>
      </geometry>
    </collision>
  </link>
  <joint name="front_right_wrist_motor_joint" type="revolute">
    <origin rpy="0.052359 2e-06 1.570846" xyz="2.3096291961e-06 1.6529780064e-03 -2.5792573351e-07"/>
    <parent link="front_right_leg_link"/>
    <child link="front_right_wrist_motor_link"/>
    <axis xyz="-1.0 -0.0 -0.0"/>
    <limit effort="1000.0" lower="-2.530727" upper="0.872665" velocity="100.0"/>
  </joint>
  <link name="front_right_wrist_link">
    <inertial>
      <origin rpy="0.0 0.0 0.0" xyz="4.9815438403e-02 4.7633606258e-03 -1.3432225904e-02"/>
      <mass value="3.4510772925e-02"/>
      <inertia ixx="5.1872271825e-06" ixy="3.5299408692e-06" ixz="4.9534016051e-06" iyy="8.1417215137e-05" iyz="-4.0645688691e-07" izz="8.0957878145e-05"/>
    </inertial>
    <visual>
      <origin rpy="0.0 0.0 0.0" xyz="0.0 0.0 0.0"/>
      <geometry>
        <mesh filename="file:///home/echo/workspaces/windows_scp/install/sparke_description/share/sparke_description/src/meshes/front_right_wrist.stl" scale="0.001 0.001 0.001"/>
      </geometry>
      <material name="Sunlu_PETG"/>
    </visual>
    <collision>
      <origin rpy="0.0 0.0 0.0" xyz="0.0 0.0 0.0"/>
      <geometry>
        <mesh filename="file:///home/echo/workspaces/windows_scp/install/sparke_description/share/sparke_description/src/meshes/front_right_wrist.stl" scale="0.001 0.001 0.001"/>
      </geometry>
      <contact_coefficients kd="200" kp="50000" mu="0.35"/>
    </collision>
  </link>
  <joint name="Rigid 29_joint" type="fixed">
    <origin rpy="1.570796 1.570796 0.0" xyz="2.3706227782e-02 -1.4999999384e-02 -3.2615342478e-03"/>
    <parent link="front_right_wrist_motor_link"/>
    <child link="front_right_wrist_link"/>
  </joint>
  <link name="front_right_foot_link">
    <contact>
      <stiffness value="10000"/>
      <damping value="10"/>
      <lateral_friction value="1"/>
    </contact>
    <inertial>
      <origin rpy="0.0 0.0 0.0" xyz="-4.6576136561e-07 -4.3392831931e-08 2.9570450780e-04"/>
      <mass value="4.0608552764e-03"/>
      <inertia ixx="2.1733728280e-07" ixy="2.5575596978e-12" ixz="1.5532407831e-12" iyy="6.5290649571e-07" iyz="-2.8358355660e-12" izz="6.4783032971e-07"/>
    </inertial>
    <visual>
      <origin rpy="0.0 0.0 0.0" xyz="0.0 0.0 0.0"/>
      <geometry>
        <mesh filename="file:///home/echo/workspaces/windows_scp/install/sparke_description/share/sparke_description/src/meshes/front_right_foot.stl" scale="0.001 0.001 0.001"/>
      </geometry>
      <material name="NinjaFlex_TPU"/>
    </visual>
    <collision>
      <origin rpy="0.0 0.0 0.0" xyz="0.0 0.0 0.0"/>
      <geometry>
        <mesh filename="file:///home/echo/workspaces/windows_scp/install/sparke_description/share/sparke_description/src/meshes/front_right_foot.stl" scale="0.001 0.001 0.001"/>
      </geometry>
      <contact_coefficients kd="100" kp="10000" mu="0.8"/>
    </collision>
  </link>
  <joint name="Rigid 52_joint" type="fixed">
    <origin rpy="-0.0 1.221725 -0.0" xyz="1.2235978642e-01 2.2436615026e-03 -1.1681321796e-02"/>
    <parent link="front_right_wrist_link"/>
    <child link="front_right_foot_link"/>
  </joint>
  <link name="front_right_leg_cover_link">
    <inertial>
      <origin rpy="0.0 0.0 0.0" xyz="-6.3614409027e-02 -1.6614273998e-02 1.0795016395e-02"/>
      <mass value="3.2642879682e-02"/>
      <inertia ixx="6.5801381234e-06" ixy="-7.1353554644e-06" ixz="-2.6398701909e-06" iyy="6.1622953151e-05" iyz="7.6589996468e-07" izz="6.3092009493e-05"/>
    </inertial>
    <visual>
      <origin rpy="0.0 0.0 0.0" xyz="0.0 0.0 0.0"/>
      <geometry>
        <mesh filename="file:///home/echo/workspaces/windows_scp/install/sparke_description/share/sparke_description/src/meshes/front_right_leg_cover.stl" scale="0.001 0.001 0.001"/>
      </geometry>
      <material name="Blue_Plastic"/>
    </visual>
    <collision>
      <origin rpy="0.0 0.0 0.0" xyz="0.0 0.0 0.0"/>
      <geometry>
        <mesh filename="file:///home/echo/workspaces/windows_scp/install/sparke_description/share/sparke_description/src/meshes/front_right_leg_cover.stl" scale="0.001 0.001 0.001"/>
      </geometry>
      <contact_coefficients kd="200" kp="50000" mu="0.35"/>
    </collision>
  </link>
  <joint name="Rigid 56_joint" type="fixed">
    <origin rpy="-2e-06 0.052359 5.1e-05" xyz="2.2890274298e-09 5.6001248125e-02 9.3081252039e-10"/>
    <parent link="front_right_leg_link"/>
    <child link="front_right_leg_cover_link"/>
  </joint>
  <link name="front_right_leg_bearing_link">
    <inertial>
      <origin rpy="0.0 0.0 0.0" xyz="-8.6685400989e-16 5.6030562235e-11 -2.3512297438e-03"/>
      <mass value="5.6361452340e-03"/>
      <inertia ixx="1.2650699251e-07" ixy="-2.1710166491e-20" ixz="-1.2952467079e-20" iyy="1.2650699276e-07" iyz="-2.3906660217e-15" izz="2.2677705019e-07"/>
    </inertial>
    <visual>
      <origin rpy="0.0 0.0 0.0" xyz="0.0 0.0 0.0"/>
      <geometry>
        <mesh filename="file:///home/echo/workspaces/windows_scp/install/sparke_description/share/sparke_description/src/meshes/front_right_leg_bearing.stl" scale="0.001 0.001 0.001"/>
      </geometry>
      <material name="Steel"/>
    </visual>
    <collision>
      <origin rpy="0.0 0.0 0.0" xyz="0.0 0.0 0.0"/>
      <geometry>
        <mesh filename="file:///home/echo/workspaces/windows_scp/install/sparke_description/share/sparke_description/src/meshes/front_right_leg_bearing.stl" scale="0.001 0.001 0.001"/>
      </geometry>
    </collision>
  </link>
  <joint name="Rigid 63_joint" type="fixed">
    <origin rpy="-1.570796 0.0 3.141592" xyz="-3.9964286462e-07 -4.9999552941e-03 -4.0907933907e-07"/>
    <parent link="front_right_leg_cover_link"/>
    <child link="front_right_leg_bearing_link"/>
  </joint>
  <link name="inner_back_shoulder_link">
    <inertial>
      <origin rpy="0.0 0.0 0.0" xyz="-7.5115476362e-03 -1.7083630825e-07 1.6382552785e-02"/>
      <mass value="6.8555867356e-02"/>
      <inertia ixx="5.7862869246e-05" ixy="4.3049829091e-10" ixz="6.1047073427e-06" iyy="6.0376210712e-05" iyz="1.8466002162e-10" izz="8.1626968761e-05"/>
    </inertial>
    <visual>
      <origin rpy="0.0 0.0 0.0" xyz="0.0 0.0 0.0"/>
      <geometry>
        <mesh filename="file:///home/echo/workspaces/windows_scp/install/sparke_description/share/sparke_description/src/meshes/inner_back_shoulder.stl" scale="0.001 0.001 0.001"/>
      </geometry>
      <material name="Sunlu_PETG"/>
    </visual>
    <collision>
      <origin rpy="0.0 0.0 0.0" xyz="0.0 0.0 0.0"/>
      <geometry>
        <mesh filename="file:///home/echo/workspaces/windows_scp/install/sparke_description/share/sparke_description/src/meshes/inner_back_shoulder.stl" scale="0.001 0.001 0.001"/>
      </geometry>
      <contact_coefficients kd="200" kp="50000" mu="0.35"/>
    </collision>
  </link>
  <joint name="Rigid 2_joint" type="fixed">
    <origin rpy="3.141593 1.570796 0.0" xyz="-6.4999990463e-02 9.5345922091e-09 3.7000002861e-02"/>
    <parent link="base_link"/>
    <child link="inner_back_shoulder_link"/>
  </joint>
  <link name="back_outer_shoulder_link">
    <inertial>
      <origin rpy="0.0 0.0 0.0" xyz="6.7549462183e-04 7.6825917006e-10 2.3644006725e-03"/>
      <mass value="2.6957423176e-02"/>
      <inertia ixx="3.1060161566e-05" ixy="2.6585036690e-13" ixz="-3.2680288790e-08" iyy="1.1480283704e-05" iyz="-5.2712213033e-14" izz="4.2428019792e-05"/>
    </inertial>
    <visual>
      <origin rpy="0.0 0.0 0.0" xyz="0.0 0.0 0.0"/>
      <geometry>
        <mesh filename="file:///home/echo/workspaces/windows_scp/install/sparke_description/share/sparke_description/src/meshes/back_outer_shoulder.stl" scale="0.001 0.001 0.001"/>
      </geometry>
      <material name="Sunlu_PETG"/>
    </visual>
    <collision>
      <origin rpy="0.0 0.0 0.0" xyz="0.0 0.0 0.0"/>
      <geometry>
        <mesh filename="file:///home/echo/workspaces/windows_scp/install/sparke_description/share/sparke_description/src/meshes/back_outer_shoulder.stl" scale="0.001 0.001 0.001"/>
      </geometry>
      <contact_coefficients kd="200" kp="50000" mu="0.35"/>
    </collision>
  </link>
  <joint name="Rigid 48_joint" type="fixed">
    <origin rpy="0.0 0.0 0.0" xyz="-2.4366991980e-09 -2.8421709430e-16 5.2500000000e-02"/>
    <parent link="inner_back_shoulder_link"/>
    <child link="back_outer_shoulder_link"/>
  </joint>
  <link name="back_right_shoulder_motor_link">
    <inertial>
      <origin rpy="0.0 0.0 0.0" xyz="2.4770417463e-02 -1.5346944999e-17 9.9190738732e-03"/>
      <mass value="6.5151227692e-02"/>
      <inertia ixx="1.1288651801e-05" ixy="-1.1134501294e-20" ixz="-1.1184552052e-07" iyy="1.7807951326e-05" iyz="-1.6567946312e-11" izz="1.0838593450e-05"/>
    </inertial>
    <visual>
      <origin rpy="0.0 0.0 0.0" xyz="2.5100000000e-02 -4.4408920985e-18 1.0000000000e-02"/>
      <geometry>
        <mesh filename="file:///home/echo/workspaces/windows_scp/install/sparke_description/share/sparke_description/src/meshes/back_right_shoulder_motor.stl" scale="0.001 0.001 0.001"/>
      </geometry>
      <material name="motor"/>
    </visual>
    <collision>
      <origin rpy="0.0 0.0 0.0" xyz="2.5100000000e-02 -4.4408920985e-18 1.0000000000e-02"/>
      <geometry>
        <mesh filename="file:///home/echo/workspaces/windows_scp/install/sparke_description/share/sparke_description/src/meshes/back_right_shoulder_motor.stl" scale="0.001 0.001 0.001"/>
      </geometry>
    </collision>
  </link>
  <joint name="back_right_shoulder_motor_joint" type="revolute">
    <origin rpy="-1.068103 1.570774 -1.068103" xyz="-9.0004342461e-03 3.9000992478e-02 1.4476511425e-03"/>
    <parent link="back_outer_shoulder_link"/>
    <child link="back_right_shoulder_motor_link"/>
    <axis xyz="1.0 0.0 -0.0"/>
    <limit effort="1000.0" lower="-0.785398" upper="0.785398" velocity="100.0"/>
  </joint>
  <link name="back_right_shoulder_link">
    <inertial>
      <origin rpy="0.0 0.0 0.0" xyz="-8.9077955019e-06 -1.5208944042e-03 1.4685782418e-02"/>
      <mass value="2.9364453561e-02"/>
      <inertia ixx="6.4062059945e-06" ixy="-1.2379545470e-08" ixz="5.6097747280e-09" iyy="1.0209186052e-05" iyz="4.1877426524e-07" izz="1.1725885400e-05"/>
    </inertial>
    <visual>
      <origin rpy="0.0 0.0 0.0" xyz="0.0 0.0 0.0"/>
      <geometry>
        <mesh filename="file:///home/echo/workspaces/windows_scp/install/sparke_description/share/sparke_description/src/meshes/back_right_shoulder.stl" scale="0.001 0.001 0.001"/>
      </geometry>
      <material name="Sunlu_PETG"/>
    </visual>
    <collision>
      <origin rpy="0.0 0.0 0.0" xyz="0.0 0.0 0.0"/>
      <geometry>
        <mesh filename="file:///home/echo/workspaces/windows_scp/install/sparke_description/share/sparke_description/src/meshes/back_right_shoulder.stl" scale="0.001 0.001 0.001"/>
      </geometry>
      <contact_coefficients kd="200" kp="50000" mu="0.35"/>
    </collision>
  </link>
  <joint name="Rigid 11_joint" type="fixed">
    <origin rpy="-1.570805 -1.570763 3.141593" xyz="2.7199350095e-02 2.7500186774e-02 1.0749048248e-02"/>
    <parent link="back_right_shoulder_motor_link"/>
    <child link="back_right_shoulder_link"/>
  </joint>
  <link name="back_right_shoulder_bearing_link">
    <inertial>
      <origin rpy="0.0 0.0 0.0" xyz="3.0148293091e-16 5.6032859591e-11 2.3512298002e-03"/>
      <mass value="5.9520564163e-03"/>
      <inertia ixx="1.3359782951e-07" ixy="-2.8441740144e-21" ixz="2.2124850143e-20" iyy="1.3359782978e-07" iyz="2.5246888396e-15" izz="2.3948812052e-07"/>
    </inertial>
    <visual>
      <origin rpy="0.0 0.0 0.0" xyz="0.0 0.0 0.0"/>
      <geometry>
        <mesh filename="file:///home/echo/workspaces/windows_scp/install/sparke_description/share/sparke_description/src/meshes/back_right_shoulder_bearing.stl" scale="0.001 0.001 0.001"/>
      </geometry>
      <material name="Cobalt_Chrome"/>
    </visual>
    <collision>
      <origin rpy="0.0 0.0 0.0" xyz="0.0 0.0 0.0"/>
      <geometry>
        <mesh filename="file:///home/echo/workspaces/windows_scp/install/sparke_description/share/sparke_description/src/meshes/back_right_shoulder_bearing.stl" scale="0.001 0.001 0.001"/>
      </geometry>
    </collision>
  </link>
  <joint name="Rigid 12_joint" type="fixed">
    <origin rpy="-1.570824 -0.0 3.141548" xyz="-1.0749865922e-02 -2.1748169408e-02 2.7500033921e-02"/>
    <parent link="back_right_shoulder_link"/>
    <child link="back_right_shoulder_bearing_link"/>
  </joint>
  <link name="back_right_shoulder_reinforcement_link">
    <inertial>
      <origin rpy="0.0 0.0 0.0" xyz="-4.6572479340e-03 9.5331124904e-03 8.4629007410e-03"/>
      <mass value="2.2660325718e-02"/>
      <inertia ixx="1.5432003406e-05" ixy="-4.1387965314e-07" ixz="-3.0777192107e-07" iyy="4.5422124673e-06" iyz="-2.9735718887e-06" izz="1.5123547672e-05"/>
    </inertial>
    <visual>
      <origin rpy="0.0 0.0 0.0" xyz="0.0 0.0 0.0"/>
      <geometry>
        <mesh filename="file:///home/echo/workspaces/windows_scp/install/sparke_description/share/sparke_description/src/meshes/back_right_shoulder_reinforcement.stl" scale="0.001 0.001 0.001"/>
      </geometry>
      <material name="Prusament_PETG"/>
    </visual>
    <collision>
      <origin rpy="0.0 0.0 0.0" xyz="0.0 0.0 0.0"/>
      <geometry>
        <mesh filename="file:///home/echo/workspaces/windows_scp/install/sparke_description/share/sparke_description/src/meshes/back_right_shoulder_reinforcement.stl" scale="0.001 0.001 0.001"/>
      </geometry>
      <contact_coefficients kd="200" kp="50000" mu="0.35"/>
    </collision>
  </link>
  <joint name="Rigid 16_joint" type="fixed">
    <origin rpy="-1.570796 -0.0 -1.570796" xyz="-3.3371861108e-02 2.5071821888e-03 -1.3628472706e-02"/>
    <parent link="back_right_shoulder_link"/>
    <child link="back_right_shoulder_reinforcement_link"/>
  </joint>
  <link name="back_right_reinforcement_bearing_link">
    <inertial>
      <origin rpy="0.0 0.0 0.0" xyz="3.0148293091e-16 5.6032859591e-11 2.3512298002e-03"/>
      <mass value="5.9520564163e-03"/>
      <inertia ixx="1.3359782951e-07" ixy="-2.8441740144e-21" ixz="2.2124850143e-20" iyy="1.3359782978e-07" iyz="2.5246888396e-15" izz="2.3948812052e-07"/>
    </inertial>
    <visual>
      <origin rpy="0.0 0.0 0.0" xyz="0.0 0.0 0.0"/>
      <geometry>
        <mesh filename="file:///home/echo/workspaces/windows_scp/install/sparke_description/share/sparke_description/src/meshes/back_right_reinforcement_bearing.stl" scale="0.001 0.001 0.001"/>
      </geometry>
      <material name="Cobalt_Chrome"/>
    </visual>
    <collision>
      <origin rpy="0.0 0.0 0.0" xyz="0.0 0.0 0.0"/>
      <geometry>
        <mesh filename="file:///home/echo/workspaces/windows_scp/install/sparke_description/share/sparke_description/src/meshes/back_right_reinforcement_bearing.stl" scale="0.001 0.001 0.001"/>
      </geometry>
    </collision>
  </link>
  <joint name="Rigid 20_joint" type="fixed">
    <origin rpy="-1.570796 0.0 0.0" xyz="2.5071670580e-03 3.5246565463e-02 3.3371712009e-02"/>
    <parent link="back_right_shoulder_reinforcement_link"/>
    <child link="back_right_reinforcement_bearing_link"/>
  </joint>
  <link name="back_right_leg_motor_link">
    <inertial>
      <origin rpy="0.0 0.0 0.0" xyz="2.4770417463e-02 6.8575154932e-18 -9.9190738732e-03"/>
      <mass value="6.5151227692e-02"/>
      <inertia ixx="1.1288651801e-05" ixy="-1.1134501294e-20" ixz="1.1184552052e-07" iyy="1.7807951326e-05" iyz="1.6567946287e-11" izz="1.0838593450e-05"/>
    </inertial>
    <visual>
      <origin rpy="0.0 0.0 0.0" xyz="2.5100000000e-02 1.7763568394e-17 -1.0000000000e-02"/>
      <geometry>
        <mesh filename="file:///home/echo/workspaces/windows_scp/install/sparke_description/share/sparke_description/src/meshes/back_right_leg_motor.stl" scale="0.001 0.001 0.001"/>
      </geometry>
      <material name="motor"/>
    </visual>
    <collision>
      <origin rpy="0.0 0.0 0.0" xyz="2.5100000000e-02 1.7763568394e-17 -1.0000000000e-02"/>
      <geometry>
        <mesh filename="file:///home/echo/workspaces/windows_scp/install/sparke_description/share/sparke_description/src/meshes/back_right_leg_motor.stl" scale="0.001 0.001 0.001"/>
      </geometry>
    </collision>
  </link>
  <joint name="back_right_leg_motor_joint" type="revolute">
    <origin rpy="0.652574 1.570795 -1.616354" xyz="1.6788098163e-07 7.4256394456e-09 2.7999343907e-03"/>
    <parent link="back_right_shoulder_link"/>
    <child link="back_right_leg_motor_link"/>
    <axis xyz="-1.0 0.0 0.0"/>
    <limit effort="1000.0" lower="-2.181662" upper="1.832596" velocity="100.0"/>
  </joint>
  <link name="back_right_leg_link">
    <inertial>
      <origin rpy="0.0 0.0 0.0" xyz="-5.4606863575e-02 2.3375791873e-02 1.0302959638e-02"/>
      <mass value="6.6453546159e-02"/>
      <inertia ixx="1.0985156700e-05" ixy="6.1976523397e-06" ixz="-2.7426543313e-06" iyy="6.1091216708e-05" iyz="-1.4569549428e-07" izz="6.3549678677e-05"/>
    </inertial>
    <visual>
      <origin rpy="0.0 0.0 0.0" xyz="0.0 0.0 0.0"/>
      <geometry>
        <mesh filename="file:///home/echo/workspaces/windows_scp/install/sparke_description/share/sparke_description/src/meshes/back_right_leg.stl" scale="0.001 0.001 0.001"/>
      </geometry>
      <material name="Sunlu_PETG"/>
    </visual>
    <collision>
      <origin rpy="0.0 0.0 0.0" xyz="0.0 0.0 0.0"/>
      <geometry>
        <mesh filename="file:///home/echo/workspaces/windows_scp/install/sparke_description/share/sparke_description/src/meshes/back_right_leg.stl" scale="0.001 0.001 0.001"/>
      </geometry>
      <contact_coefficients kd="200" kp="50000" mu="0.35"/>
    </collision>
  </link>
  <joint name="Rigid 31_joint" type="fixed">
    <origin rpy="1.570796 1.570796 0.0" xyz="4.9499961853e-03 1.3819298880e-02 -1.0742515781e-01"/>
    <parent link="back_right_leg_motor_link"/>
    <child link="back_right_leg_link"/>
  </joint>
  <link name="back_right_wrist_motor_link">
    <inertial>
      <origin rpy="0.0 0.0 0.0" xyz="2.4770417463e-02 -1.0906052901e-17 -9.9190738732e-03"/>
      <mass value="6.5151227692e-02"/>
      <inertia ixx="1.1288651801e-05" ixy="-1.1134501294e-20" ixz="1.1184552052e-07" iyy="1.7807951326e-05" iyz="1.6567946287e-11" izz="1.0838593450e-05"/>
    </inertial>
    <visual>
      <origin rpy="0.0 0.0 0.0" xyz="2.5100000000e-02 0.0000000000e+00 -1.0000000000e-02"/>
      <geometry>
        <mesh filename="file:///home/echo/workspaces/windows_scp/install/sparke_description/share/sparke_description/src/meshes/back_right_wrist_motor.stl" scale="0.001 0.001 0.001"/>
      </geometry>
      <material name="motor"/>
    </visual>
    <collision>
      <origin rpy="0.0 0.0 0.0" xyz="2.5100000000e-02 0.0000000000e+00 -1.0000000000e-02"/>
      <geometry>
        <mesh filename="file:///home/echo/workspaces/windows_scp/install/sparke_description/share/sparke_description/src/meshes/back_right_wrist_motor.stl" scale="0.001 0.001 0.001"/>
      </geometry>
    </collision>
  </link>
  <joint name="back_right_wrist_motor_joint" type="revolute">
    <origin rpy="0.052359 2e-06 1.570846" xyz="2.3096291961e-06 1.6529780064e-03 -2.5792573350e-07"/>
    <parent link="back_right_leg_link"/>
    <child link="back_right_wrist_motor_link"/>
    <axis xyz="-1.0 0.0 0.0"/>
    <limit effort="1000.0" lower="-2.530727" upper="0.872665" velocity="100.0"/>
  </joint>
  <link name="back_right_wrist_link">
    <inertial>
      <origin rpy="0.0 0.0 0.0" xyz="4.9815438403e-02 4.7633606258e-03 -1.3432225904e-02"/>
      <mass value="3.4510772925e-02"/>
      <inertia ixx="5.1872271825e-06" ixy="3.5299408692e-06" ixz="4.9534016051e-06" iyy="8.1417215137e-05" iyz="-4.0645688691e-07" izz="8.0957878145e-05"/>
    </inertial>
    <visual>
      <origin rpy="0.0 0.0 0.0" xyz="0.0 0.0 0.0"/>
      <geometry>
        <mesh filename="file:///home/echo/workspaces/windows_scp/install/sparke_description/share/sparke_description/src/meshes/back_right_wrist.stl" scale="0.001 0.001 0.001"/>
      </geometry>
      <material name="Sunlu_PETG"/>
    </visual>
    <collision>
      <origin rpy="0.0 0.0 0.0" xyz="0.0 0.0 0.0"/>
      <geometry>
        <mesh filename="file:///home/echo/workspaces/windows_scp/install/sparke_description/share/sparke_description/src/meshes/back_right_wrist.stl" scale="0.001 0.001 0.001"/>
      </geometry>
      <contact_coefficients kd="200" kp="50000" mu="0.35"/>
    </collision>
  </link>
  <joint name="Rigid 34_joint" type="fixed">
    <origin rpy="1.570796 1.570796 0.0" xyz="2.3706227782e-02 -1.4999999384e-02 -3.2615342478e-03"/>
    <parent link="back_right_wrist_motor_link"/>
    <child link="back_right_wrist_link"/>
  </joint>
  <link name="back_right_foot_link">
    <contact>
      <stiffness value="10000"/>
      <damping value="10"/>
      <lateral_friction value="1"/>
    </contact>
    <inertial>
      <origin rpy="0.0 0.0 0.0" xyz="-4.6576136561e-07 -4.3392831931e-08 2.9570450780e-04"/>
      <mass value="4.0608552764e-03"/>
      <inertia ixx="2.1733728280e-07" ixy="2.5575596978e-12" ixz="1.5532407831e-12" iyy="6.5290649571e-07" iyz="-2.8358355660e-12" izz="6.4783032971e-07"/>
    </inertial>
    <visual>
      <origin rpy="0.0 0.0 0.0" xyz="0.0 0.0 0.0"/>
      <geometry>
        <mesh filename="file:///home/echo/workspaces/windows_scp/install/sparke_description/share/sparke_description/src/meshes/back_right_foot.stl" scale="0.001 0.001 0.001"/>
      </geometry>
      <material name="NinjaFlex_TPU"/>
    </visual>
    <collision>
      <origin rpy="0.0 0.0 0.0" xyz="0.0 0.0 0.0"/>
      <geometry>
        <mesh filename="file:///home/echo/workspaces/windows_scp/install/sparke_description/share/sparke_description/src/meshes/back_right_foot.stl" scale="0.001 0.001 0.001"/>
      </geometry>
      <contact_coefficients kd="100" kp="10000" mu="0.8"/>
    </collision>
  </link>
  <joint name="Rigid 54_joint" type="fixed">
    <origin rpy="0.0 1.221725 0.0" xyz="1.2235978642e-01 2.2436615026e-03 -1.1681321796e-02"/>
    <parent link="back_right_wrist_link"/>
    <child link="back_right_foot_link"/>
  </joint>
  <link name="back_right_leg_cover_link">
    <inertial>
      <origin rpy="0.0 0.0 0.0" xyz="-6.3614409027e-02 -1.6614273998e-02 1.0795016395e-02"/>
      <mass value="3.2642879682e-02"/>
      <inertia ixx="6.5801381234e-06" ixy="-7.1353554644e-06" ixz="-2.6398701909e-06" iyy="6.1622953151e-05" iyz="7.6589996468e-07" izz="6.3092009493e-05"/>
    </inertial>
    <visual>
      <origin rpy="0.0 0.0 0.0" xyz="0.0 0.0 0.0"/>
      <geometry>
        <mesh filename="file:///home/echo/workspaces/windows_scp/install/sparke_description/share/sparke_description/src/meshes/back_right_leg_cover.stl" scale="0.001 0.001 0.001"/>
      </geometry>
      <material name="Blue_Plastic"/>
    </visual>
    <collision>
      <origin rpy="0.0 0.0 0.0" xyz="0.0 0.0 0.0"/>
      <geometry>
        <mesh filename="file:///home/echo/workspaces/windows_scp/install/sparke_description/share/sparke_description/src/meshes/back_right_leg_cover.stl" scale="0.001 0.001 0.001"/>
      </geometry>
      <contact_coefficients kd="200" kp="50000" mu="0.35"/>
    </collision>
  </link>
  <joint name="Rigid 58_joint" type="fixed">
    <origin rpy="-2e-06 0.052359 5.1e-05" xyz="2.2890275275e-09 5.6001248125e-02 9.3081267138e-10"/>
    <parent link="back_right_leg_link"/>
    <child link="back_right_leg_cover_link"/>
  </joint>
  <link name="back_right_leg_bearing_link">
    <inertial>
      <origin rpy="0.0 0.0 0.0" xyz="-8.6685400989e-16 5.6030562235e-11 -2.3512297438e-03"/>
      <mass value="5.6361452340e-03"/>
      <inertia ixx="1.2650699251e-07" ixy="-2.1710166491e-20" ixz="-1.2952467079e-20" iyy="1.2650699276e-07" iyz="-2.3906660217e-15" izz="2.2677705019e-07"/>
    </inertial>
    <visual>
      <origin rpy="0.0 0.0 0.0" xyz="0.0 0.0 0.0"/>
      <geometry>
        <mesh filename="file:///home/echo/workspaces/windows_scp/install/sparke_description/share/sparke_description/src/meshes/back_right_leg_bearing.stl" scale="0.001 0.001 0.001"/>
      </geometry>
      <material name="Steel"/>
    </visual>
    <collision>
      <origin rpy="0.0 0.0 0.0" xyz="0.0 0.0 0.0"/>
      <geometry>
        <mesh filename="file:///home/echo/workspaces/windows_scp/install/sparke_description/share/sparke_description/src/meshes/back_right_leg_bearing.stl" scale="0.001 0.001 0.001"/>
      </geometry>
    </collision>
  </link>
  <joint name="Rigid 62_joint" type="fixed">
    <origin rpy="-1.570796 0.0 3.141592" xyz="-3.9964286460e-07 -4.9999552941e-03 -4.0907933908e-07"/>
    <parent link="back_right_leg_cover_link"/>
    <child link="back_right_leg_bearing_link"/>
  </joint>
  <link name="back_left_shoulder_motor_link">
    <inertial>
      <origin rpy="0.0 0.0 0.0" xyz="2.4770417463e-02 -1.5346944999e-17 -9.9190738732e-03"/>
      <mass value="6.5151227692e-02"/>
      <inertia ixx="1.1288651801e-05" ixy="-1.1134501294e-20" ixz="1.1184552052e-07" iyy="1.7807951326e-05" iyz="1.6567946287e-11" izz="1.0838593450e-05"/>
    </inertial>
    <visual>
      <origin rpy="0.0 0.0 0.0" xyz="2.5100000000e-02 -4.4408920985e-18 -1.0000000000e-02"/>
      <geometry>
        <mesh filename="file:///home/echo/workspaces/windows_scp/install/sparke_description/share/sparke_description/src/meshes/back_left_shoulder_motor.stl" scale="0.001 0.001 0.001"/>
      </geometry>
      <material name="motor"/>
    </visual>
    <collision>
      <origin rpy="0.0 0.0 0.0" xyz="2.5100000000e-02 -4.4408920985e-18 -1.0000000000e-02"/>
      <geometry>
        <mesh filename="file:///home/echo/workspaces/windows_scp/install/sparke_description/share/sparke_description/src/meshes/back_left_shoulder_motor.stl" scale="0.001 0.001 0.001"/>
      </geometry>
    </collision>
  </link>
  <joint name="back_left_shoulder_motor_joint" type="revolute">
    <origin rpy="-2.07349 1.570774 1.068103" xyz="-9.0004342461e-03 -3.9000975487e-02 1.4476511425e-03"/>
    <parent link="back_outer_shoulder_link"/>
    <child link="back_left_shoulder_motor_link"/>
    <axis xyz="-1.0 -0.0 -0.0"/>
    <limit effort="1000.0" lower="-0.785398" upper="0.785398" velocity="100.0"/>
  </joint>
  <link name="back_left_shoulder_link">
    <inertial>
      <origin rpy="0.0 0.0 0.0" xyz="-8.9121600367e-06 -1.5211509529e-03 -1.4685633137e-02"/>
      <mass value="2.9364763609e-02"/>
      <inertia ixx="6.4063207202e-06" ixy="-1.2324133327e-08" ixz="-5.5676552781e-09" iyy="1.0209381952e-05" iyz="-4.1881957681e-07" izz="1.1726316518e-05"/>
    </inertial>
    <visual>
      <origin rpy="0.0 0.0 0.0" xyz="0.0 0.0 0.0"/>
      <geometry>
        <mesh filename="file:///home/echo/workspaces/windows_scp/install/sparke_description/share/sparke_description/src/meshes/back_left_shoulder.stl" scale="0.001 0.001 0.001"/>
      </geometry>
      <material name="Sunlu_PETG"/>
    </visual>
    <collision>
      <origin rpy="0.0 0.0 0.0" xyz="0.0 0.0 0.0"/>
      <geometry>
        <mesh filename="file:///home/echo/workspaces/windows_scp/install/sparke_description/share/sparke_description/src/meshes/back_left_shoulder.stl" scale="0.001 0.001 0.001"/>
      </geometry>
      <contact_coefficients kd="200" kp="50000" mu="0.35"/>
    </collision>
  </link>
  <joint name="Rigid 9_joint" type="fixed">
    <origin rpy="1.570805 1.570763 3.141593" xyz="2.7199350095e-02 2.7500186774e-02 -1.0749048248e-02"/>
    <parent link="back_left_shoulder_motor_link"/>
    <child link="back_left_shoulder_link"/>
  </joint>
  <link name="back_left_shoulder_bearing_link">
    <inertial>
      <origin rpy="0.0 0.0 0.0" xyz="-8.6685400989e-16 5.6030562235e-11 -2.3512297438e-03"/>
      <mass value="5.9520565592e-03"/>
      <inertia ixx="1.3359783030e-07" ixy="-2.2927042065e-20" ixz="-1.3678465234e-20" iyy="1.3359783057e-07" iyz="-2.5246651363e-15" izz="2.3948812052e-07"/>
    </inertial>
    <visual>
      <origin rpy="0.0 0.0 0.0" xyz="0.0 0.0 0.0"/>
      <geometry>
        <mesh filename="file:///home/echo/workspaces/windows_scp/install/sparke_description/share/sparke_description/src/meshes/back_left_shoulder_bearing.stl" scale="0.001 0.001 0.001"/>
      </geometry>
      <material name="Cobalt_Chrome"/>
    </visual>
    <collision>
      <origin rpy="0.0 0.0 0.0" xyz="0.0 0.0 0.0"/>
      <geometry>
        <mesh filename="file:///home/echo/workspaces/windows_scp/install/sparke_description/share/sparke_description/src/meshes/back_left_shoulder_bearing.stl" scale="0.001 0.001 0.001"/>
      </geometry>
    </collision>
  </link>
  <joint name="Rigid 10_joint" type="fixed">
    <origin rpy="1.570824 0.0 3.141548" xyz="-1.0749865922e-02 -2.1748169408e-02 -2.7500033921e-02"/>
    <parent link="back_left_shoulder_link"/>
    <child link="back_left_shoulder_bearing_link"/>
  </joint>
  <link name="back_left_shoulder_reinforcement_link">
    <inertial>
      <origin rpy="0.0 0.0 0.0" xyz="-4.6571345170e-03 9.5334507238e-03 -8.4629481940e-03"/>
      <mass value="2.2660594722e-02"/>
      <inertia ixx="1.5432217957e-05" ixy="-4.1394328355e-07" ixz="3.0777468508e-07" iyy="4.5423320189e-06" iyz="2.9736040956e-06" izz="1.5123941735e-05"/>
    </inertial>
    <visual>
      <origin rpy="0.0 0.0 0.0" xyz="0.0 0.0 0.0"/>
      <geometry>
        <mesh filename="file:///home/echo/workspaces/windows_scp/install/sparke_description/share/sparke_description/src/meshes/back_left_shoulder_reinforcement.stl" scale="0.001 0.001 0.001"/>
      </geometry>
      <material name="Prusament_PETG"/>
    </visual>
    <collision>
      <origin rpy="0.0 0.0 0.0" xyz="0.0 0.0 0.0"/>
      <geometry>
        <mesh filename="file:///home/echo/workspaces/windows_scp/install/sparke_description/share/sparke_description/src/meshes/back_left_shoulder_reinforcement.stl" scale="0.001 0.001 0.001"/>
      </geometry>
      <contact_coefficients kd="200" kp="50000" mu="0.35"/>
    </collision>
  </link>
  <joint name="Rigid 15_joint" type="fixed">
    <origin rpy="1.570796 0.0 -1.570796" xyz="-3.3371861108e-02 2.5071821888e-03 1.3628472706e-02"/>
    <parent link="back_left_shoulder_link"/>
    <child link="back_left_shoulder_reinforcement_link"/>
  </joint>
  <link name="back_left_reinforcement_bearing_link">
    <inertial>
      <origin rpy="0.0 0.0 0.0" xyz="-8.6685400989e-16 5.6030562235e-11 -2.3512297438e-03"/>
      <mass value="5.9520565592e-03"/>
      <inertia ixx="1.3359783030e-07" ixy="-2.2927042065e-20" ixz="-1.3678465234e-20" iyy="1.3359783057e-07" iyz="-2.5246651363e-15" izz="2.3948812052e-07"/>
    </inertial>
    <visual>
      <origin rpy="0.0 0.0 0.0" xyz="0.0 0.0 0.0"/>
      <geometry>
        <mesh filename="file:///home/echo/workspaces/windows_scp/install/sparke_description/share/sparke_description/src/meshes/back_left_reinforcement_bearing.stl" scale="0.001 0.001 0.001"/>
      </geometry>
      <material name="Cobalt_Chrome"/>
    </visual>
    <collision>
      <origin rpy="0.0 0.0 0.0" xyz="0.0 0.0 0.0"/>
      <geometry>
        <mesh filename="file:///home/echo/workspaces/windows_scp/install/sparke_description/share/sparke_description/src/meshes/back_left_reinforcement_bearing.stl" scale="0.001 0.001 0.001"/>
      </geometry>
    </collision>
  </link>
  <joint name="Rigid 19_joint" type="fixed">
    <origin rpy="1.570796 0.0 0.0" xyz="2.5071670580e-03 3.5246565463e-02 -3.3371712009e-02"/>
    <parent link="back_left_shoulder_reinforcement_link"/>
    <child link="back_left_reinforcement_bearing_link"/>
  </joint>
  <link name="back_left_leg_motor_link">
    <inertial>
      <origin rpy="0.0 0.0 0.0" xyz="2.4770417463e-02 -1.0906052901e-17 9.9190738732e-03"/>
      <mass value="6.5151227692e-02"/>
      <inertia ixx="1.1288651801e-05" ixy="-1.1134501294e-20" ixz="-1.1184552052e-07" iyy="1.7807951326e-05" iyz="-1.6567946312e-11" izz="1.0838593450e-05"/>
    </inertial>
    <visual>
      <origin rpy="0.0 0.0 0.0" xyz="2.5100000000e-02 0.0000000000e+00 1.0000000000e-02"/>
      <geometry>
        <mesh filename="file:///home/echo/workspaces/windows_scp/install/sparke_description/share/sparke_description/src/meshes/back_left_leg_motor.stl" scale="0.001 0.001 0.001"/>
      </geometry>
      <material name="motor"/>
    </visual>
    <collision>
      <origin rpy="0.0 0.0 0.0" xyz="2.5100000000e-02 0.0000000000e+00 1.0000000000e-02"/>
      <geometry>
        <mesh filename="file:///home/echo/workspaces/windows_scp/install/sparke_description/share/sparke_description/src/meshes/back_left_leg_motor.stl" scale="0.001 0.001 0.001"/>
      </geometry>
    </collision>
  </link>
  <joint name="back_left_leg_motor_joint" type="revolute">
    <origin rpy="-0.652574 -1.570795 -1.616354" xyz="1.6788098166e-07 7.4256394100e-09 -2.7999343907e-03"/>
    <parent link="back_left_shoulder_link"/>
    <child link="back_left_leg_motor_link"/>
    <axis xyz="1.0 -0.0 0.0"/>
    <limit effort="1000.0" lower="-2.181662" upper="1.832596" velocity="100.0"/>
  </joint>
  <link name="back_left_leg_link">
    <inertial>
      <origin rpy="0.0 0.0 0.0" xyz="-5.4606100052e-02 2.3375508028e-02 -1.0302815208e-02"/>
      <mass value="6.6454472204e-02"/>
      <inertia ixx="1.0985672324e-05" ixy="6.1986854700e-06" ixz="2.7421282493e-06" iyy="6.1094164263e-05" iyz="1.4589221151e-07" izz="6.3552877469e-05"/>
    </inertial>
    <visual>
      <origin rpy="0.0 0.0 0.0" xyz="0.0 0.0 0.0"/>
      <geometry>
        <mesh filename="file:///home/echo/workspaces/windows_scp/install/sparke_description/share/sparke_description/src/meshes/back_left_leg.stl" scale="0.001 0.001 0.001"/>
      </geometry>
      <material name="Sunlu_PETG"/>
    </visual>
    <collision>
      <origin rpy="0.0 0.0 0.0" xyz="0.0 0.0 0.0"/>
      <geometry>
        <mesh filename="file:///home/echo/workspaces/windows_scp/install/sparke_description/share/sparke_description/src/meshes/back_left_leg.stl" scale="0.001 0.001 0.001"/>
      </geometry>
      <contact_coefficients kd="200" kp="50000" mu="0.35"/>
    </collision>
  </link>
  <joint name="Rigid 36_joint" type="fixed">
    <origin rpy="-1.570796 -1.570796 0.0" xyz="4.9499961853e-03 1.3819298880e-02 1.0742515781e-01"/>
    <parent link="back_left_leg_motor_link"/>
    <child link="back_left_leg_link"/>
  </joint>
  <link name="back_left_wrist_motor_link">
    <inertial>
      <origin rpy="0.0 0.0 0.0" xyz="2.4770417463e-02 -6.4196758083e-17 9.9190738732e-03"/>
      <mass value="6.5151227692e-02"/>
      <inertia ixx="1.1288651801e-05" ixy="-1.1134501294e-20" ixz="-1.1184552052e-07" iyy="1.7807951326e-05" iyz="-1.6567946312e-11" izz="1.0838593450e-05"/>
    </inertial>
    <visual>
      <origin rpy="0.0 0.0 0.0" xyz="2.5100000000e-02 -5.3290705182e-17 1.0000000000e-02"/>
      <geometry>
        <mesh filename="file:///home/echo/workspaces/windows_scp/install/sparke_description/share/sparke_description/src/meshes/back_left_wrist_motor.stl" scale="0.001 0.001 0.001"/>
      </geometry>
      <material name="motor"/>
    </visual>
    <collision>
      <origin rpy="0.0 0.0 0.0" xyz="2.5100000000e-02 -5.3290705182e-17 1.0000000000e-02"/>
      <geometry>
        <mesh filename="file:///home/echo/workspaces/windows_scp/install/sparke_description/share/sparke_description/src/meshes/back_left_wrist_motor.stl" scale="0.001 0.001 0.001"/>
      </geometry>
    </collision>
  </link>
  <joint name="back_left_wrist_motor_joint" type="revolute">
    <origin rpy="-0.052359 -2e-06 1.570846" xyz="2.3096291961e-06 1.6529780064e-03 2.5792573353e-07"/>
    <parent link="back_left_leg_link"/>
    <child link="back_left_wrist_motor_link"/>
    <axis xyz="1.0 0.0 0.0"/>
    <limit effort="1000.0" lower="-2.530727" upper="0.872665" velocity="100.0"/>
  </joint>
  <link name="back_left_wrist_link">
    <inertial>
      <origin rpy="0.0 0.0 0.0" xyz="4.9747178430e-02 4.7847093617e-03 1.3421230556e-02"/>
      <mass value="3.4551036819e-02"/>
      <inertia ixx="5.2044527700e-06" ixy="3.5730960450e-06" ixz="-4.9756329095e-06" iyy="8.1559081128e-05" iyz="4.1340818971e-07" izz="8.1109521282e-05"/>
    </inertial>
    <visual>
      <origin rpy="0.0 0.0 0.0" xyz="0.0 0.0 0.0"/>
      <geometry>
        <mesh filename="file:///home/echo/workspaces/windows_scp/install/sparke_description/share/sparke_description/src/meshes/back_left_wrist.stl" scale="0.001 0.001 0.001"/>
      </geometry>
      <material name="Sunlu_PETG"/>
    </visual>
    <collision>
      <origin rpy="0.0 0.0 0.0" xyz="0.0 0.0 0.0"/>
      <geometry>
        <mesh filename="file:///home/echo/workspaces/windows_scp/install/sparke_description/share/sparke_description/src/meshes/back_left_wrist.stl" scale="0.001 0.001 0.001"/>
      </geometry>
      <contact_coefficients kd="200" kp="50000" mu="0.35"/>
    </collision>
  </link>
  <joint name="Rigid 39_joint" type="fixed">
    <origin rpy="-1.570796 -1.570796 0.0" xyz="2.3706227782e-02 -1.4999999384e-02 3.2615342478e-03"/>
    <parent link="back_left_wrist_motor_link"/>
    <child link="back_left_wrist_link"/>
  </joint>
  <link name="back_left_foot_link">
    <contact>
      <stiffness value="10000"/>
      <damping value="10"/>
      <lateral_friction value="1"/>
    </contact>
    <inertial>
      <origin rpy="0.0 0.0 0.0" xyz="-6.2511651463e-07 1.4767339683e-08 -2.9531449039e-04"/>
      <mass value="4.0610139569e-03"/>
      <inertia ixx="2.1736705869e-07" ixy="3.2711759586e-12" ixz="3.0436497378e-12" iyy="6.5294667216e-07" iyz="-5.8438631289e-13" izz="6.4784298190e-07"/>
    </inertial>
    <visual>
      <origin rpy="0.0 0.0 0.0" xyz="0.0 0.0 0.0"/>
      <geometry>
        <mesh filename="file:///home/echo/workspaces/windows_scp/install/sparke_description/share/sparke_description/src/meshes/back_left_foot.stl" scale="0.001 0.001 0.001"/>
      </geometry>
      <material name="NinjaFlex_TPU"/>
    </visual>
    <collision>
      <origin rpy="0.0 0.0 0.0" xyz="0.0 0.0 0.0"/>
      <geometry>
        <mesh filename="file:///home/echo/workspaces/windows_scp/install/sparke_description/share/sparke_description/src/meshes/back_left_foot.stl" scale="0.001 0.001 0.001"/>
      </geometry>
      <contact_coefficients kd="100" kp="10000" mu="0.8"/>
    </collision>
  </link>
  <joint name="Rigid 53_joint" type="fixed">
    <origin rpy="0.0 -1.221725 -0.0" xyz="1.2235978642e-01 2.2436615026e-03 1.1681321796e-02"/>
    <parent link="back_left_wrist_link"/>
    <child link="back_left_foot_link"/>
  </joint>
  <link name="back_left_leg_cover_link">
    <inertial>
      <origin rpy="0.0 0.0 0.0" xyz="-6.3642567032e-02 -1.6626829366e-02 -1.0807825161e-02"/>
      <mass value="3.2616672507e-02"/>
      <inertia ixx="6.5685289932e-06" ixy="-7.1216478366e-06" ixz="2.6597436857e-06" iyy="6.1594213073e-05" iyz="-7.6240704761e-07" izz="6.3063527195e-05"/>
    </inertial>
    <visual>
      <origin rpy="0.0 0.0 0.0" xyz="0.0 0.0 0.0"/>
      <geometry>
        <mesh filename="file:///home/echo/workspaces/windows_scp/install/sparke_description/share/sparke_description/src/meshes/back_left_leg_cover.stl" scale="0.001 0.001 0.001"/>
      </geometry>
      <material name="Blue_Plastic"/>
    </visual>
    <collision>
      <origin rpy="0.0 0.0 0.0" xyz="0.0 0.0 0.0"/>
      <geometry>
        <mesh filename="file:///home/echo/workspaces/windows_scp/install/sparke_description/share/sparke_description/src/meshes/back_left_leg_cover.stl" scale="0.001 0.001 0.001"/>
      </geometry>
      <contact_coefficients kd="200" kp="50000" mu="0.35"/>
    </collision>
  </link>
  <joint name="Rigid 59_joint" type="fixed">
    <origin rpy="2e-06 -0.052359 5.1e-05" xyz="2.2890274565e-09 5.6001248125e-02 -9.3081260921e-10"/>
    <parent link="back_left_leg_link"/>
    <child link="back_left_leg_cover_link"/>
  </joint>
  <link name="back_left_leg_bearing_link">
    <inertial>
      <origin rpy="0.0 0.0 0.0" xyz="3.0148293091e-16 5.6032859591e-11 2.3512298002e-03"/>
      <mass value="5.6361450987e-03"/>
      <inertia ixx="1.2650699176e-07" ixy="-2.6932166482e-21" ixz="2.0950551704e-20" iyy="1.2650699201e-07" iyz="2.3906884669e-15" izz="2.2677705019e-07"/>
    </inertial>
    <visual>
      <origin rpy="0.0 0.0 0.0" xyz="0.0 0.0 0.0"/>
      <geometry>
        <mesh filename="file:///home/echo/workspaces/windows_scp/install/sparke_description/share/sparke_description/src/meshes/back_left_leg_bearing.stl" scale="0.001 0.001 0.001"/>
      </geometry>
      <material name="Steel"/>
    </visual>
    <collision>
      <origin rpy="0.0 0.0 0.0" xyz="0.0 0.0 0.0"/>
      <geometry>
        <mesh filename="file:///home/echo/workspaces/windows_scp/install/sparke_description/share/sparke_description/src/meshes/back_left_leg_bearing.stl" scale="0.001 0.001 0.001"/>
      </geometry>
    </collision>
  </link>
  <joint name="Rigid 60_joint" type="fixed">
    <origin rpy="1.570796 -0.0 3.141592" xyz="-3.9964286458e-07 -4.9999552941e-03 4.0907933908e-07"/>
    <parent link="back_left_leg_cover_link"/>
    <child link="back_left_leg_bearing_link"/>
  </joint>
  <link name="right_base_link">
    <inertial>
      <origin rpy="0.0 0.0 0.0" xyz="2.7489749806e-09 1.2259250005e-04 2.6307145511e-03"/>
      <mass value="1.2942461333e-02"/>
      <inertia ixx="1.2104319541e-06" ixy="2.0127242362e-14" ixz="-5.9652157015e-14" iyy="2.6795947958e-05" iyz="-1.7759160536e-09" izz="2.7899947462e-05"/>
    </inertial>
    <visual>
      <origin rpy="0.0 0.0 0.0" xyz="0.0 0.0 0.0"/>
      <geometry>
        <mesh filename="file:///home/echo/workspaces/windows_scp/install/sparke_description/share/sparke_description/src/meshes/right_base.stl" scale="0.001 0.001 0.001"/>
      </geometry>
      <material name="Sunlu_PETG"/>
    </visual>
    <collision>
      <origin rpy="0.0 0.0 0.0" xyz="0.0 0.0 0.0"/>
      <geometry>
        <mesh filename="file:///home/echo/workspaces/windows_scp/install/sparke_description/share/sparke_description/src/meshes/right_base.stl" scale="0.001 0.001 0.001"/>
      </geometry>
      <contact_coefficients kd="200" kp="50000" mu="0.35"/>
    </collision>
  </link>
  <joint name="Rigid 3_joint" type="fixed">
    <origin rpy="-1.570796 0.0 0.0" xyz="9.5367432884e-09 -5.4999994899e-02 3.9500006436e-02"/>
    <parent link="base_link"/>
    <child link="right_base_link"/>
  </joint>
  <link name="left_base_link">
    <inertial>
      <origin rpy="0.0 0.0 0.0" xyz="2.7489749806e-09 1.2259250005e-04 2.6307145511e-03"/>
      <mass value="1.2942461333e-02"/>
      <inertia ixx="1.2104319541e-06" ixy="2.0127242362e-14" ixz="-5.9652157015e-14" iyy="2.6795947958e-05" iyz="-1.7759160536e-09" izz="2.7899947462e-05"/>
    </inertial>
    <visual>
      <origin rpy="0.0 0.0 0.0" xyz="0.0 0.0 0.0"/>
      <geometry>
        <mesh filename="file:///home/echo/workspaces/windows_scp/install/sparke_description/share/sparke_description/src/meshes/left_base.stl" scale="0.001 0.001 0.001"/>
      </geometry>
      <material name="Sunlu_PETG"/>
    </visual>
    <collision>
      <origin rpy="0.0 0.0 0.0" xyz="0.0 0.0 0.0"/>
      <geometry>
        <mesh filename="file:///home/echo/workspaces/windows_scp/install/sparke_description/share/sparke_description/src/meshes/left_base.stl" scale="0.001 0.001 0.001"/>
      </geometry>
      <contact_coefficients kd="200" kp="50000" mu="0.35"/>
    </collision>
  </link>
  <joint name="Rigid 4_joint" type="fixed">
    <origin rpy="-1.570796 0.0 -3.141593" xyz="9.5367431463e-09 5.5000007504e-02 3.9500006436e-02"/>
    <parent link="base_link"/>
    <child link="left_base_link"/>
  </joint>
</robot>
